Workbook

Sheet Gen CP
A1: Republic of the Phillipines
A2: Region III
A3: Schools Division of Nueva Ecija
A4: Schools Division of Nueva Ecija
A5: Sagaba, Sto. Domingo, Nueva Ecija
A7: GRADE 11 SHS GENERAL CLASS SCHEDULE
A8: First Semester S.Y. 2024-2025
Q9: GRADE 11 | AF9: GRADE 12
A10: TIME | B10: STEM | C10: HumSS A | D10: HumSS B | E10: HumSS C | F10: HumSS D | G10: HumSS E | H10: AGRI | I10: INDUSTRIAL ARTS | J10: ICT | K10: GAS | L10: H.E. | M10: International
B11: Hierco M | C11: R Coronel | D11: Sagnip M | E11: R.Estrella | F11: Aguilar EM | G11: Mamaid MC | H11: D Reyes | I11: AJD Almazan | J11: Guerrero LG | K11: Valdez R | L11: Maniquiz T | M11: Lorenzana C
B12: 11B | C12: 14B | D12: 6B | E12: 2B | F12: 5B | G12: 13B | H12: 8B | I12: 5A | J12: 14A | K12: 13A | L12: 4B
B13: Teacher A | D13: Teacher E | I13: C Lorenzo | K13: R Crisostomo | L13: Teacher B
A14: 7:00-7:20 | B14: FLAG CEREMONY/ROOM and GROUND IMPROVEMENT
A15: 7:20-8:10 | B15: Earth Science | C15: MIL | D15: Oral Com | E15: UCSP | F15: Kom Pan | G15: UCSP | H15: Agri-Crops NC II | I15: Earth & Life | J15: Emp Tech | K15: UCSP | L15: Food and Beverage | AY15: Loads
B16: Hierco M | C16: Coronel R | D16: Sagnip M | E16: Estrella R | F16: Aguilar EM | G16: Mamaid MC | H16: Reyes D | I16: Almazan AD | J16: Guerrero LG | K16: Valdez R | L16: Maniquiz T | N16: Crisostomo R | Q16: =B16 -> Hierco M | R16: =C16 -> Coronel R | S16: =D16 -> Sagnip M | T16: =E16 -> Estrella R | U16: =F16 -> Aguilar EM | V16: =G16 -> Mamaid MC | W16: =H16 -> Reyes D | X16: =I16 -> Almazan AD | ... AE16: =P16 -> 0 | AF16: =B59 -> Bartolome H | AG16: =C59 -> Orgil E | AH16: =D59 -> Sarmiento F | AI16: =E59 -> Almadin H | AJ16: =F59 -> Pascua I | AK16: =G59 -> Tamondong A | AL16: =H59 -> De Leon I | AM16: =I59 -> Mercado R | ... AT16: =P59 -> 0 | AX16: =Old!B3 -> Aguilar EM | AY16: =COUNTIF(Q$16:AT$35,"Aguilar EM") -> 7
A17: 8:10-9:00 | B17: Pre-Calculus | C17: Kom Pan | D17: UCSP | E17: Oral Com | F17: 21st Cen Lit | G17: Earth & Life | H17: Agri-Crops NC II | I17: Oral Com | J17: Gen Math | K17: Earth & Life | L17: Food and Beverage | AX17: =Old!B4 -> Almadin H | AY17: =COUNTIF(Q$16:AT$35,"Almadin H") -> 7
B18: Lorenzana C | C18: Aguilar EM | D18: Estrella R | E18: Sagnip M | F18: Crisostomo R | G18: Almazan AD | H18: Reyes D | I18: Tamondong A | J18: Domingo V | K18: Marcelo OJ | L18: Maniquiz T | N18: Bartolome H | Q18: =B18 -> Lorenzana C | R18: =C18 -> Aguilar EM | S18: =D18 -> Estrella R | T18: =E18 -> Sagnip M | U18: =F18 -> Crisostomo R | V18: =G18 -> Almazan AD | W18: =H18 -> Reyes D | X18: =I18 -> Tamondong A | ... AE18: =P18 -> 0 | AF18: =B61 -> Orgil E | AG18: =C61 -> Lorenzo C | AH18: =D61 -> Almadin H | AI18: =E61 -> Gardoce J | AJ18: =F61 -> Hierco M | AK18: =G61 -> Carillo R | AL18: =H61 -> Valdez R | AM18: =I61 -> Mercado R | ... AT18: =P61 -> 0 | AX18: =Old!B5 -> Almazan AD | AY18: =COUNTIF(Q$16:AT$35,"Almazan AD") -> 7
A19: 9:00-9:30 | B19: RECESS | AX19: =Old!B6 -> Bartolome H | AY19: =COUNTIF(Q$16:AT$35,"Bartolome H") -> 7
A20: 9:30-10:20 | B20: Gen Math | C20: 21st Cen Lit | D20: Kom Pan | E20: Earth & Life | F20: Oral Com | G20: MIL | H20: UCSP | I20: SMAW NC I | J20: CSS | K20: Gen Math | L20: Earth & Life | AX20: =Old!B7 -> Carillo R | AY20: =COUNTIF(Q$16:AT$35,"Carillo R") -> 7
B21: Lorenzana C | C21: Crisostomo R | D21: Aguilar EM | E21: Almazan AD | F21: Sagnip M | G21: Coronel R | H21: Estrella R | I21: Sarmiento F | J21: Mercado R | K21: Domingo V | L21: Marcelo OJ | N21: Orgil E | Q21: =B21 -> Lorenzana C | R21: =C21 -> Crisostomo R | S21: =D21 -> Aguilar EM | T21: =E21 -> Almazan AD | U21: =F21 -> Sagnip M | V21: =G21 -> Coronel R | W21: =H21 -> Estrella R | X21: =I21 -> Sarmiento F | ... AE21: =P21 -> 0 | AF21: =B64 -> De Leon I | AG21: =C64 -> Tamondong A | AH21: =D64 -> Lorenzo C | AI21: =E64 -> Hierco M | AJ21: =F64 -> Gardoce J | AK21: =G64 -> Carillo R | AL21: =H64 -> Pascua I | AM21: =I64 -> Bartolome H | ... AT21: =P64 -> 0 | AX21: =Old!B8 -> Coronel R | AY21: =COUNTIF(Q$16:AT$35,"Coronel R") -> 7
A22: 10:20-11:10 | B22: UCSP | C22: Gen Math | D22: 21st Cen Lit | E22: MIL | F22: Gen Math | G22: Emp Tech | H22: Earth & Life | I22: SMAW NC I | J22: CSS | K22: Kom Pan | L22: Oral Com | AX22: =Old!B9 -> Crisostomo R | AY22: =COUNTIF(Q$16:AT$35,"Crisostomo R") -> 7
B23: Estrella R | C23: Lorenzana C | D23: Crisostomo R | E23: Coronel R | F23: Domingo V | G23: Reyes D | H23: Almazan AD | I23: Sarmiento F | J23: Mercado R | K23: Aguilar EM | L23: Sagnip M | N23: De Leon I | Q23: =B23 -> Estrella R | R23: =C23 -> Lorenzana C | S23: =D23 -> Crisostomo R | T23: =E23 -> Coronel R | U23: =F23 -> Domingo V | V23: =G23 -> Reyes D | W23: =H23 -> Almazan AD | X23: =I23 -> Sarmiento F | ... AE23: =P23 -> 0 | AF23: =B66 -> Hierco M | AG23: =C66 -> Marcelo OJ | AH23: =D66 -> Bartolome H | AI23: =E66 -> Lorenzo C | AJ23: =F66 -> Almadin H | AK23: =G66 -> Carillo R | AL23: =H66 -> Orgil E | AM23: =I66 -> Valdez R | ... AT23: =P66 -> 0 | AX23: =Old!B10 -> De Leon I | AY23: =COUNTIF(Q$16:AT$35,"De Leon I") -> 5
A24: 11:10-12:00 | B24: Chemistry 1 | C24: UCSP | D24: Emp Tech | E24: 21st Cen Lit | F24: Earth & Life | G24: Oral Com | H24: Gen Math | I24: Kom Pan | J24: Oral Com | K24: Creative Writing | L24: Gen Math | AX24: =Old!B11 -> Domingo V | AY24: =COUNTIF(Q$16:AT$35,"Domingo V") -> 7
B25: Orgil E | C25: Estrella R | D25: Reyes D | E25: Crisostomo R | F25: Marcelo OJ | G25: Sagnip M | H25: Domingo V | I25: Pascua I | J25: Coronel R | K25: Sarmiento F | L25: Lorenzana C | Q25: =B25 -> Orgil E | R25: =C25 -> Estrella R | S25: =D25 -> Reyes D | T25: =E25 -> Crisostomo R | U25: =F25 -> Marcelo OJ | V25: =G25 -> Sagnip M | W25: =H25 -> Domingo V | X25: =I25 -> Pascua I | ... AE25: =P25 -> 0 | AF25: =B68 -> Lorenzo C | AG25: =C68 -> De Leon I | AH25: =D68 -> Tamondong A | AI25: =E68 -> Carillo R | AJ25: =F68 -> Bartolome H | AK25: =G68 -> Maniquiz T | AL25: =H68 -> Valdez R | AM25: =I68 -> Hierco M | ... AT25: =P68 -> 0 | AX25: =Old!B12 -> Estrella R | AY25: =COUNTIF(Q$16:AT$35,"Estrella R") -> 7
A26: 12:00-1:00 | B26: LUNCH | AX26: =Old!B13 -> Gardoce J | AY26: =COUNTIF(Q$16:AT$35,"Gardoce J") -> 7
A27: 1:00-1:50 | B27: Kom Pan | C27: Earth & Life | D27: MIL | E27: Emp Tech | F27: Emp Tech | G27: Gen Math | H27: Oral Com | I27: Emp Tech | J27: Earth & Life | K27: Organ Man | L27: Kom Pan | AX27: =Old!B14 -> Guerrero LG | AY27: =COUNTIF(Q$16:AT$35,"Guerrero LG") -> 4
B28: Aguilar EM | C28: Marcelo OJ | D28: Coronel R | E28: Reyes D | F28: Mercado R | G28: Domingo V | H28: Sagnip M | I28: Guerrero LG | J28: Almazan AD | K28: Almadin H | L28: Pascua I | N28: Orgil E | Q28: =B28 -> Aguilar EM | R28: =C28 -> Marcelo OJ | S28: =D28 -> Coronel R | T28: =E28 -> Reyes D | U28: =F28 -> Mercado R | V28: =G28 -> Domingo V | W28: =H28 -> Sagnip M | X28: =I28 -> Guerrero LG | ... AE28: =P28 -> 0 | AF28: =B71 -> Sarmiento F | AG28: =C71 -> Gardoce J | AH28: =D71 -> Carillo R | AI28: =E71 -> Tamondong A | AJ28: =F71 -> Mamaid MC | AK28: =G71 -> Lorenzo C | AL28: =H71 -> Bartolome H | AM28: =I71 -> De Leon I | ... AT28: =P71 -> 0 | AX28: =Old!B15 -> Hierco M | AY28: =COUNTIF(Q$16:AT$35,"Hierco M") -> 7
A29: 1:50-2:40 | B29: Emp Tech | C29: Emp Tech | D29: Earth & Life | E29: Gen Math | F29: MIL | G29: Kom Pan | H29: Kom Pan | I29: UCSP | J29: UCSP | K29: Oral Com | L29: Emp Tech | AX29: =Old!B16 -> Lorenzana C | AY29: =COUNTIF(Q$16:AT$35,"Lorenzana C") -> 6
B30: Mercado R | C30: Guerrero LG | D30: Almazan AD | E30: Lorenzana C | F30: Coronel R | G30: Pascua I | H30: Aguilar EM | I30: Mamaid MC | J30: Estrella R | K30: Tamondong A | L30: Reyes D | N30: Hierco M | Q30: =B30 -> Mercado R | R30: =C30 -> Guerrero LG | S30: =D30 -> Almazan AD | T30: =E30 -> Lorenzana C | U30: =F30 -> Coronel R | V30: =G30 -> Pascua I | W30: =H30 -> Aguilar EM | X30: =I30 -> Mamaid MC | ... AE30: =P30 -> 0 | AF30: =B73 -> Crisostomo R | AG30: =C73 -> Almadin H | AH30: =D73 -> Gardoce J | AI30: =E73 -> Marcelo OJ | AJ30: =F73 -> Carillo R | AK30: =G73 -> Valdez R | AL30: =H73 -> Sarmiento F | AM30: =I73 -> Lorenzo C | ... AT30: =P73 -> 0 | AX30: =Old!B17 -> Lorenzo C | AY30: =COUNTIF(Q$16:AT$35,"Lorenzo C") -> 7
A31: 2:40-3:10 | AX31: =Old!B18 -> Mamaid MC | AY31: =COUNTIF(Q$16:AT$35,"Mamaid MC") -> 7
A32: 3:00-4:00 3:10-4:00 | B32: Oral Com | C32: Oral Com | D32: Gen Math | E32: Kom Pan | F32: UCSP | G32: 21st Cen Lit | H32: Emp Tech | I32: Gen Math | J32: Kom Pan | K32: Emp Tech | L32: UCSP | AX32: =Old!B19 -> Maniquiz T | AY32: =COUNTIF(Q$16:AT$35,"Maniquiz T") -> 6
B33: Coronel R | C33: Sagnip M | D33: Lorenzana C | E33: Aguilar EM | F33: Estrella R | G33: Crisostomo R | H33: Reyes D | I33: Almazan AD | J33: Pascua I | K33: Mercado R | L33: Mamaid MC | N33: Domingo V | Q33: =B33 -> Coronel R | R33: =C33 -> Sagnip M | S33: =D33 -> Lorenzana C | T33: =E33 -> Aguilar EM | U33: =F33 -> Estrella R | V33: =G33 -> Crisostomo R | W33: =H33 -> Reyes D | X33: =I33 -> Almazan AD | ... AE33: =P33 -> 0 | AF33: =B76 -> Orgil E | AG33: =C76 -> Carillo R | AH33: =D76 -> Hierco M | AI33: =E76 -> Guerrero LG | AJ33: =F76 -> Tamondong A | AK33: =G76 -> Gardoce J | AL33: =H76 -> Sarmiento F | AM33: =I76 -> Almadin H | ... AT33: =P76 -> 0 | AX33: =Old!B20 -> Marcelo OJ | AY33: =COUNTIF(Q$16:AT$35,"Marcelo OJ") -> 7
A34: P.E. & Health | B34: P.E. and Health | C34: P.E. and Health | D34: P.E. and Health | E34: P.E. and Health | F34: P.E. and Health | G34: P.E. and Health | H34: P.E. and Health | I34: P.E. and Health | J34: P.E. and Health | K34: P.E. and Health | L34: P.E. and Health | AX34: =Old!B21 -> Mercado R | AY34: =COUNTIF(Q$16:AT$35,"Mercado R") -> 7
B35: LG Guerrero | C35: LG Guerrero | D35: LG Guerrero | E35: LG Guerrero | F35: LG Guerrero | G35: LG Guerrero | H35: LG Guerrero | I35: LG Guerrero | J35: LG Guerrero | K35: LG Guerrero | L35: LG Guerrero | Q35: =B35 -> LG Guerrero | R35: =C35 -> LG Guerrero | S35: =D35 -> LG Guerrero | T35: =E35 -> LG Guerrero | U35: =F35 -> LG Guerrero | V35: =G35 -> LG Guerrero | W35: =H35 -> LG Guerrero | X35: =I35 -> LG Guerrero | ... AE35: =P35 -> 0 | AF35: =B78 -> I De Leon | AG35: =C78 -> I De Leon | AH35: =D78 -> I De Leon | AI35: =E78 -> I De Leon | AJ35: =F78 -> I De Leon | AK35: =G78 -> I De Leon | AL35: =H78 -> I De Leon | AM35: =I78 -> LG Guerrero | ... AT35: =P78 -> 0 | AX35: =Old!B22 -> Orgil E | AY35: =COUNTIF(Q$16:AT$35,"Orgil E") -> 7
A36: Teaching Loads | B36: =AY28 -> 7 | C36: =AY21 -> 7 | D36: =AY38 -> 7 | E36: =AY25 -> 7 | F36: =AY16 -> 7 | G36: =AY31 -> 7 | H36: =AY37 -> 7 | I36: =AY18 -> 7 | J36: =AY27 -> 4 | K36: =AY41 -> 7 | L36: =AY32 -> 6 | M36: =AY29 -> 6 | AX36: =Old!B23 -> Pascua I | AY36: =COUNTIF(Q$16:AT$35,"Pascua I") -> 7
B37: =AY42 -> 0 | J37: 11 | K37: =AY22 -> 7 | L37: =AY43 -> 0 | AX37: =Old!B24 -> Reyes D | AY37: =COUNTIF(Q$16:AT$35,"Reyes D") -> 7
A38: HGP* See Class Schedule | AX38: =Old!B25 -> Sagnip M | AY38: =COUNTIF(Q$16:AT$35,"Sagnip M") -> 7
A39: Prepared by: | G39: Checked by: | M39: Approved by: | AX39: =Old!B26 -> Sarmiento F | AY39: =COUNTIF(Q$16:AT$35,"Sarmiento F") -> 7
AX40: =Old!B27 -> Tamondong A | AY40: =COUNTIF(Q$16:AT$35,"Tamondong A") -> 7
AX41: =Old!B28 -> Valdez R | AY41: =COUNTIF(Q$16:AT$35,"Valdez R") -> 7
...

Sheet Ref
A1: STEM
A2: As per Division Memo # 102 s. 2018
A3: CORE SUBJECTS | B3: 1st Semester | D3: 2nd Semester | F3: 3rd Semester | H3: 4th Semester
B4: Oral Com | D4: Reading and Writing | F4: 21st Cen Lit | H4: English for Academic
B5: Kom Pan | D5: Pagbasa | F5: MIL | H5: HGP
B6: Earth Science | D6: DRRR | F6: CPAR
B7: Gen Math | D7: Stat and Prob | F7: HGP
B8: UCSP | D8: Personal Development | F8: Philo
B9: P.E. and Health | D9: P.E. and Health | F9: P.E. and Health | H9: P.E. and Health
A10: Concenptualized Subjects | B10: Emp Tech | D10: Research 1 | F10: Research 2 | H10: Entrepreneurship
B11: HGP | D11: HGP | F11: Piling Larang | H11: Research Project
A12: Specialization Subjects | B12: Pre-Calculus | D12: Basic Calculus | F12: Biology 1 | H12: Biology 2
B13: Chemistry 1 | D13: Chemistry 2 | F13: Physics 1 | H13: Physics 2
F14: HGP | H14: Capstone Project
A28: HUMSS
A29: As per Division Memo # 102 s. 2018
A30: CORE SUBJECTS | B30: 1st Semester | D30: 2nd Semester | F30: 3rd Semester | H30: 4th Semester
B31: Oral Com | D31: Reading and Writing | F31: CPAR | H31: English for Academic
B32: Kom Pan | D32: Pagbasa | F32: Philo | H32: HGP
B33: Earth & Life | D33: Physical Science | F33: HGP
B34: Gen Math | D34: Stat and Prob
B35: UCSP | D35: Personal Development
B36: 21st Cen Lit
B37: MIL | F37: Philo
B38: P.E. and Health | D38: P.E. and Health | F38: P.E. and Health | H38: P.E. and Health
A39: Concenptualized Subjects | B39: Emp Tech | D39: Research 1 | F39: Research 2 | H39: Entrepreneurship
B40: HGP | D40: HGP | F40: Piling Larang | H40: Research Project
A41: Specialization Subjects | D41: Creative Writing | F41: World Religions | H41: TNCTCC
D42: DISS | F42: Creative Non-Fiction | H42: CESC
F43: PPG | H43: Culminating Activity
F44: DIASS
A58: GAS
A59: As per Division Memo # 102 s. 2018
A60: CORE SUBJECTS | B60: 1st Semester | D60: 2nd Semester | F60: 3rd Semester | H60: 4th Semester
B61: Oral Com | D61: Reading and Writing | F61: 21st Cen Lit | H61: English for Academic
B62: Kom Pan | D62: Pagbasa | F62: MIL
B63: Earth & Life | D63: Physical Science | F63: CPAR
B64: Gen Math | D64: Stat and Prob
B65: UCSP | D65: Personal Development | F65: Philo
B66: HGP | D66: HGP | F66: HGP | H66: HGP
...

Sheet New
A1: STEM
A2: As per Division Memo # 102 s. 2018
A3: CORE SUBJECTS | B3: 1st Semester | D3: 2nd Semester | F3: 3rd Semester | H3: 4th Semester
B4: Oral Communication | D4: Reading and Writing Skills | F4: 21st Century Literature from the Philippines and the World
B5: Komunikasyon at Pananaliksik sa Wika at Kulturang Pilipino | D5: Pagbasa at Pagsusuri ng Iba't Ibang Teksto Tungo sa Pananaliksik | F5: Media and Information Literacy
B6: Earth Science | D6: Disaster Readiness and Risk Reduction | F6: Contemporary Philippine Arts from the Regions
B7: General Mathematics | D7: Statistics and Probability
B8: Understanding Culture, Society and Politics | D8: Personal Development | F8: Introduction to the Philosophy of the Human Person
B9: Physical Education and Health | D9: Physical Education and Health | F9: Physical Education and Health | H9: Physical Education and Health
A10: Concenptualized Subjects | B10: Empowerment Technologies | D10: Practical Research 1 | F10: Practical Research 2 | H10: English for Academic and Professional Purposes
F11: Filipino sa Piling Larang | H11: Entrepreneurship
H12: Inquiries, Investigations and Immersion(Research Project)
A13: Specialized Subjects | B13: Pre-Calculus | D13: Basic Calculus | F13: General Biology 1 | H13: General Biology 2
B14: General Chemistry 1 | D14: General Chemistry 2 | F14: General Physics 1 | H14: General Physics 2
H15: Capstone Project
A16: Subject | C16: Pre-requisite/s | F16: Subject | H16: Pre-requisite/s
A17: Practical Research 2 | C17: Statistics and Probability | F17: Inquiries, Investigations and Immersion(Research Project) | H17: Practical Research 1
A18: General Chemistry 2 | C18: General Chemistry 1 | H18: Practical Research 2
A19: General Biology 2 | C19: General Biology 1
A20: General Physics 2 | C20: General Physics 1
A21: Basic Calculus | C21: Pre-Calculus
A30: HUMSS
A31: As per Division Memo # 102 s. 2018
A32: CORE SUBJECTS | B32: 1st Semester | D32: 2nd Semester | F32: 3rd Semester | H32: 4th Semester
B33: Oral Communication | D33: Reading and Writing Skills | F33: Contemporary Philippine Arts from the Regions
B34: Komunikasyon at Pananaliksik sa Wika at Kulturang Pilipino | D34: Pagbasa at Pagsusuri ng Iba't Ibang Teksto Tungo sa Pananaliksik | F34: Introduction to the Philosophy of the Human Person
B35: Earth and Life Science | D35: Physical Science
B36: General Mathematics | D36: Statistics and Probability
B37: Understanding Culture, Society and Politics | D37: Personal Development
B38: 21st Century Literarure from the Phillipines and the World
B39: Media and Information Literacy
B40: Physical Education and Health | D40: Physical Education and Health | F40: Physical Education and Health | H40: Physical Education and Health
A41: Concenptualized Subjects | B41: Empowerment Technologies | D41: Practical Research 1 | F41: Practical Research 2 | H41: English for Academic and Professional Purposes
F42: Filipino sa Piling Larang | H42: Entrepreneurship
H43: Inquiries, Investigations and Immersion(Research Project)
A44: Specialization Subjects | D44: Creative Writing | F44: Introduction to World Religions | H44: Trends, Networks and Critical Thinking in the 21st Century Culture(TNCTCC)
D45: Disciplines and Ideas in the Social Sciences(DISS) | F45: Creative Non-Fiction | H45: Community Engagement, Solidarity and Citizenship
F46: Philippine Politics and Governance | H46: Culminating Activity/Work Immersion
F47: Disciplines and Ideas in the Applied Social Sciences(DIASS)
A48: Subject | C48: Pre-requisite/s | F48: Subject | H48: Pre-requisite/s
...

Sheet Old
A1: Teachers' Profile | C1: Applied and Specialized Subjects | M1: Core Subjects
L2: STRAND
A3: 1 | B3: Aguilar EM | C3: English for Academic and Professional Purposes | J3: English for Academic | L3: Common | M3: Oral Communication | U3: Oral Com
A4: 2 | B4: Almadin H | C4: Practical Research 1 | J4: Research 1 | L4: Common | M4: Reading and Writing | U4: R & W
A5: 3 | B5: Almazan AD | C5: Practical Research 2 | J5: Rsearch 2 | L5: Common | M5: Komunikasyon at Pananaliksik sa Wika at Kulturang Pilipino | U5: Kom Pan
A6: 4 | B6: Bartolome H | C6: Filipino sa Piling Larang | J6: Piling Larang | L6: Common | M6: Pagbasa at Pagsusuri ng Iba't Ibang Teksto Tungo sa Pananaliksik | U6: Pagbasa
A7: 5 | B7: Carillo R | C7: Empowerment Technologies | J7: Empowerment | L7: Common | M7: 21st Century Literature from the Philippines and the World | U7: 21st Century
A8: 6 | B8: Coronel R | C8: Entrepreneurship | J8: Entrepreneurship | L8: Common | M8: Contemporary Philippine Arts from the Regions | U8: CPAR
A9: 7 | B9: Crisostomo R | C9: Inquiries, Investigations and Immersion(Research Project) | J9: Rrsearch Project | L9: Common | M9: Media and Information Literacy | U9: Media
A10: 8 | B10: De Leon I | C10: Pre-Calculus | J10: Pre-Calculus | L10: STEM | M10: General Mathematics | U10: Gen Math
A11: 9 | B11: Domingo V | C11: Basic Calculus | J11: Basic Calculus | L11: STEM | M11: Statistics and Probability | U11: Stat & Prob
A12: 10 | B12: Estrella R | C12: General Biology 1 | J12: General Biology 1 | L12: STEM | M12: Earth and Life Science | U12: Earth & Life
A13: 11 | B13: Gardoce J | C13: General Biology 2 | J13: General Biology 2 | L13: STEM | M13: Physical Science | U13: Physical Sci
A14: 12 | B14: Guerrero LG | C14: General Chemistry 1 | J14: General Chemistry 1 | L14: STEM | M14: Personal Development/Pansariling Kaunlaran | U14: Per Dev
... A17: 15 | B17: Lorenzo C | C17: General Physics 2 | J17: General Physics 2 | L17: STEM | M17: Physical Education and Health | U17: P.E. & Health
A18: 16 | B18: Mamaid MC | C18: Capstone Project | J18: Capstone Project | L18: STEM | M18: Earth Science | Q18: STEM only | U18: Earth Science
A19: 17 | B19: Maniquiz T | C19: Creative Writing | J19: Creative Writing | L19: GAS/HUMSS | M19: Disaster Readiness and Risk Reduction | Q19: STEM only | U19: DRRR
A20: 18 | B20: Marcelo OJ | C20: Creative Nonfiction | J20: Creative Nonfiction | L20: HUMSS
A21: 19 | B21: Mercado R | C21: Disciplines and Ideas in the Social Sciences | J21: DISS | L21: HUMSS
A22: 20 | B22: Orgil E | C22: Introduction to World Religions | J22: Religion | L22: HUMSS
A23: 21 | B23: Pascua I | C23: Philippine Politics and Governance | J23: PPG | L23: GAS/HUMSS
A24: 22 | B24: Reyes D | C24: Disciplines and Ideas in the Applied Social Sciences | J24: DIASS | L24: HUMSS
A25: 23 | B25: Sagnip M | C25: Community Engagement, Solidarity and Citizenship | J25: CESC | L25: HUMSS
A26: 24 | B26: Sarmiento F | C26: Trends, Networks and Critical Thinking in the 21st Century Culture | J26: TNCTCC | L26: HUMSS/GAS
A27: 25 | B27: Tamondong A | C27: Culminating Activity | J27: Culminating | L27: HUMSS
A28: 26 | B28: Valdez R | C28: Organization and Management | J28: Organ-Man | L28: GAS
A29: Science A | B29: Teacher A | C29: Disaster Readiness and Risk Reduction | J29: DRRR | L29: GAS
A30: Science B | B30: Teacher B | C30: Applied Economics | J30: Economics | L30: GAS
A31: Soc Sci | B31: Teacher C | C31: Business Mathematics | J31: Business Math | L31: GAS
A32: SMAW | B32: Teacher D | C32: Principles of Marketing | J32: Marketing | L32: GAS
A33: English | B33: Teacher E | C33: Work Immersion | J33: Work Immersion
A34: 32 | B34: I De Leon | C34: Food and Beverage Services | J34: Food & Beverage | L34: H.E.
A35: 33 | B35: LG Guerrero | C35: Bread and Pastry | J35: Bread and Pastry | L35: H.E.
A36: 34 | C36: Cookery | J36: Cookery | L36: H.E.
A37: 35 | C37: Agricrops | J37: Agricrops | L37: AGRI
A38: 36 | C38: Shielded Metal Arc Welding (NC I) | J38: SMAW NC I | L38: IA
A39: 37 | C39: Shielded Metal Arc Welding (NC II) | J39: SMAW NC II | L39: IA
A40: 38 | C40: Animation | J40: Animation | L40: IACT
A41: 39 | C41: Computer System Servicing (NC-II) | J41: CSS NC II | L41: ICT
A42: 40 | C42: CAT(Optional) | L42: ALL
...

Sheet Class Sch
A1: Republic of the Philippines | M1: Republic of the Philippines | Y1: Republic of the Philippines | AK1: Republic of the Philippines | BI1: Republic of the Philippines | BU1: Republic of the Philippines | CG1: Republic of the Philippines | CS1: Republic of the Philippines | DE1: Republic of the Philippines | DQ1: Republic of the Philippines | EC1: Republic of the Philippines | EO1: Republic of the Philippines | FA1: Republic of the Philippines | FM1: Republic of the Philippines | FY1: Republic of the Philippines
A2: Region III | M2: Region III | Y2: Region III | AK2: Region III | AW2: Region III | BI2: Region III | BU2: Region III | CG2: Region III | CS2: Region III | DE2: Region III | DQ2: Region III | EC2: Region III | EO2: Region III | FA2: Region III | FM2: Region III | FY2: Region III
A3: Schools Division of Nueva Ecija | M3: Schools Division of Nueva Ecija | Y3: Schools Division of Nueva Ecija | AK3: Schools Division of Nueva Ecija | BI3: Schools Division of Nueva Ecija | BU3: Schools Division of Nueva Ecija | CG3: Schools Division of Nueva Ecija | CS3: Schools Division of Nueva Ecija | DE3: Schools Division of Nueva Ecija | DQ3: Schools Division of Nueva Ecija | EC3: Schools Division of Nueva Ecija | EO3: Schools Division of Nueva Ecija | FA3: Schools Division of Nueva Ecija | FM3: Schools Division of Nueva Ecija | FY3: Schools Division of Nueva Ecija
A4: SHS-JULIA ORTIZ LUIS NATIONAL HIGH SCHOOL | M4: SHS-JULIA ORTIZ LUIS NATIONAL HIGH SCHOOL | Y4: SHS-JULIA ORTIZ LUIS NATIONAL HIGH SCHOOL | AK4: SHS-JULIA ORTIZ LUIS NATIONAL HIGH SCHOOL | AW4: SHS-JULIA ORTIZ LUIS NATIONAL HIGH SCHOOL | BI4: SHS-JULIA ORTIZ LUIS NATIONAL HIGH SCHOOL | BU4: SHS-JULIA ORTIZ LUIS NATIONAL HIGH SCHOOL | CG4: SHS-JULIA ORTIZ LUIS NATIONAL HIGH SCHOOL | CS4: SHS-JULIA ORTIZ LUIS NATIONAL HIGH SCHOOL | DE4: SHS-JULIA ORTIZ LUIS NATIONAL HIGH SCHOOL | DQ4: SHS-JULIA ORTIZ LUIS NATIONAL HIGH SCHOOL | EC4: SHS-JULIA ORTIZ LUIS NATIONAL HIGH SCHOOL | EO4: SHS-JULIA ORTIZ LUIS NATIONAL HIGH SCHOOL | FA4: SHS-JULIA ORTIZ LUIS NATIONAL HIGH SCHOOL | FM4: SHS-JULIA ORTIZ LUIS NATIONAL HIGH SCHOOL | FY4: SHS-JULIA ORTIZ LUIS NATIONAL HIGH SCHOOL
A5: Sagaba, Sto. Domongo, Nueva Ecija | M5: Sagaba, Sto. Domongo, Nueva Ecija | Y5: Sagaba, Sto. Domongo, Nueva Ecija | AK5: Sagaba, Sto. Domongo, Nueva Ecija | AW5: Sagaba, Sto. Domongo, Nueva Ecija | BI5: Sagaba, Sto. Domongo, Nueva Ecija | BU5: Sagaba, Sto. Domongo, Nueva Ecija | CG5: Sagaba, Sto. Domongo, Nueva Ecija | CS5: Sagaba, Sto. Domongo, Nueva Ecija | DE5: Sagaba, Sto. Domongo, Nueva Ecija | DQ5: Sagaba, Sto. Domongo, Nueva Ecija | EC5: Sagaba, Sto. Domongo, Nueva Ecija | EO5: Sagaba, Sto. Domongo, Nueva Ecija | FA5: Sagaba, Sto. Domongo, Nueva Ecija | FM5: Sagaba, Sto. Domongo, Nueva Ecija | FY5: Sagaba, Sto. Domongo, Nueva Ecija
A7: CLASS SCHEDULE | M7: CLASS SCHEDULE | Y7: CLASS SCHEDULE | AK7: CLASS SCHEDULE | AW7: CLASS SCHEDULE | BI7: CLASS SCHEDULE | BU7: CLASS SCHEDULE | CG7: CLASS SCHEDULE | CS7: CLASS SCHEDULE | DE7: CLASS SCHEDULE | DQ7: CLASS SCHEDULE | EC7: CLASS SCHEDULE | EO7: CLASS SCHEDULE | FA7: CLASS SCHEDULE | FM7: CLASS SCHEDULE | FY7: CLASS SCHEDULE
A8: Adviser: | B8: MAUREEN A. HIERCO | I8: Grade 11-STEM | M8: Adviser: | N8: ROMARC B CORONEL | U8: Grade 11-HumSS A | Y8: Adviser: | Z8: MARIEFE M SAGNIP | AG8: Grade 11-HumSS B | AK8: Adviser: | AL8: ROMNICK T. ESTRELLA | AS8: Grade 11-HumSS C | AW8: Adviser: | AX8: ELENA MARIE A AGUILAR | BE8: Grade 11-HumSS D | BI8: Adviser: | BJ8: MERRY CHRISTINE B. MAMAID | BQ8: Grade 11 HumSS E | BU8: Adviser: | BV8: DARWIN E, REYES | CC8: Grade 11-AFA | CG8: Adviser: | CH8: ANGEL JOY DIANNE ALMAZAN | CO8: Grade 11-SMAW | CS8: Adviser: | CT8: LOVELY GRACE GUERRERO | DA8: Grade 11-ICT | DE8: Adviser: | DF8: REALINE S VALDEZ | DM8: Grade 11-GAS | DQ8: Adviser: | DR8: TERESITA N. MANIQUIZ | DY8: Grade 11-H.E. | EC8: Adviser: | EK8: Grade 11-H.E. | EO8: Adviser: | EP8: Romeo DR. Crisostomo | EW8: Grade 11-GAS | FA8: Adviser: | FB8: Romeo DR. Crisostomo | FI8: Grade 11-GAS | FM8: Adviser: | FN8: Romeo DR. Crisostomo | FU8: Grade 11-GAS | FY8: Adviser: | GG8: Grade 11-COOKERY/GAS B
B9: Teacher III | I9: ='Gen CP'!A8 -> First Semester S.Y. 2024-2025 | N9: Teacher III | U9: =I9 -> First Semester S.Y. 2024-2025 | Z9: Teacher II | AG9: =U9 -> First Semester S.Y. 2024-2025 | AL9: Teacher II | AS9: =AG9 -> First Semester S.Y. 2024-2025 | AX9: Teacher II | BE9: =AS9 -> First Semester S.Y. 2024-2025 | BJ9: Teacher II | BQ9: =BE9 -> First Semester S.Y. 2024-2025 | BV9: Teacher III | CC9: =BQ9 -> First Semester S.Y. 2024-2025 | CH9: Teacher II | CO9: =CC9 -> First Semester S.Y. 2024-2025 | CT9: Teacher II | DA9: =CO9 -> First Semester S.Y. 2024-2025 | DF9: Teacher II | DM9: =DA9 -> First Semester S.Y. 2024-2025 | DR9: Teacher III | DY9: =DM9 -> First Semester S.Y. 2024-2025 | EK9: =DY9 -> First Semester S.Y. 2024-2025 | EP9: Teacher II | EW9: First Semester S.Y. 2022-2023 | FB9: Teacher II | FI9: First Semester S.Y. 2022-2023 | FN9: Teacher II | FU9: First Semester S.Y. 2022-2023 | FZ9: Teacher III | GG9: =EK9 -> First Semester S.Y. 2024-2025
A11: Time | B11: No. of Minutes | C11: MONDAY | E11: TUESDAY | G11: WEDNESDAY | I11: THURSDAY | K11: FRIDAY | M11: Time | N11: No. of Minutes | O11: MONDAY | Q11: TUESDAY | S11: WEDNESDAY | U11: THURSDAY | W11: FRIDAY | Y11: Time | Z11: No. of Minutes | AA11: MONDAY | AC11: TUESDAY | AE11: WEDNESDAY | AG11: THURSDAY | AI11: FRIDAY | AK11: Time | AL11: No. of Minutes | AM11: MONDAY | AO11: TUESDAY | AQ11: WEDNESDAY | AS11: THURSDAY | AU11: FRIDAY | AW11: Time | AX11: No. of Minutes | AY11: MONDAY | BA11: TUESDAY | BC11: WEDNESDAY | BE11: THURSDAY | BG11: FRIDAY | BI11: Time | BJ11: No. of Minutes | BK11: MONDAY | BM11: TUESDAY | BO11: WEDNESDAY | BQ11: THURSDAY | BS11: FRIDAY | BU11: Time | BV11: No. of Minutes | BW11: MONDAY | BY11: TUESDAY | CA11: WEDNESDAY | CC11: THURSDAY | CE11: FRIDAY | CG11: Time | CH11: No. of Minutes | CI11: MONDAY | CK11: TUESDAY | CM11: WEDNESDAY | CO11: THURSDAY | CQ11: FRIDAY | CS11: Time | CT11: No. of Minutes | CU11: MONDAY | CW11: TUESDAY | CY11: WEDNESDAY | DA11: THURSDAY | DC11: FRIDAY | DE11: Time | DF11: No. of Minutes | DG11: MONDAY | DI11: TUESDAY | DK11: WEDNESDAY | DM11: THURSDAY | DO11: FRIDAY | DQ11: Time | DR11: No. of Minutes | DS11: MONDAY | DU11: TUESDAY | DW11: WEDNESDAY | DY11: THURSDAY | EA11: FRIDAY | EC11: Time | ED11: No. of Minutes | EE11: MONDAY | EG11: TUESDAY | EI11: WEDNESDAY | EK11: THURSDAY | EM11: FRIDAY | EO11: Time | EP11: No. of Minutes | EQ11: MONDAY | ES11: TUESDAY | EU11: WEDNESDAY | EW11: THURSDAY | EY11: FRIDAY | FA11: Time | FB11: No. of Minutes | FC11: MONDAY | FE11: TUESDAY | FG11: WEDNESDAY | FI11: THURSDAY | FK11: FRIDAY | FM11: Time | FN11: No. of Minutes | FO11: MONDAY | FQ11: TUESDAY | FS11: WEDNESDAY | FU11: THURSDAY | FW11: FRIDAY | FY11: Time | FZ11: No. of Minutes | GA11: MONDAY | GC11: TUESDAY | GE11: WEDNESDAY | GG11: THURSDAY | GI11: FRIDAY
A13: 7:00-7:20 | C13: PRELIMINARY ACTIVITIES | M13: 7:00-7:20 | O13: PRELIMINARY ACTIVITIES | Y13: 7:00-7:20 | AA13: PRELIMINARY ACTIVITIES | AK13: 7:00-7:20 | AM13: PRELIMINARY ACTIVITIES | AW13: 7:00-7:20 | AY13: PRELIMINARY ACTIVITIES | BI13: 7:00-7:20 | BK13: PRELIMINARY ACTIVITIES | BU13: 7:00-7:20 | BW13: PRELIMINARY ACTIVITIES | CG13: 7:00-7:20 | CI13: PRELIMINARY ACTIVITIES | CS13: 7:00-7:20 | CU13: PRELIMINARY ACTIVITIES | DE13: 7:00-7:20 | DG13: PRELIMINARY ACTIVITIES | DQ13: 7:00-7:20 | DS13: PRELIMINARY ACTIVITIES | EC13: 7:00-7:30 | EE13: PRELIMINARY ACTIVITIES | EO13: 7:00-7:30 | EQ13: PRELIMINARY ACTIVITIES | FA13: 7:00-7:30 | FC13: PRELIMINARY ACTIVITIES | FM13: 7:00-7:30 | FO13: PRELIMINARY ACTIVITIES | FY13: 7:00-7:30 | GA13: PRELIMINARY ACTIVITIES
A14: 7:20-8:10 | C14: HGP | E14: ='Gen CP'!$B15 -> Earth Science | G14: ='Gen CP'!$B15 -> Earth Science | I14: ='Gen CP'!$B15 -> Earth Science | K14: ='Gen CP'!$B15 -> Earth Science | M14: 7:20-8:10 | O14: HGP | Q14: ='Gen CP'!$C15 -> MIL | S14: ='Gen CP'!$C15 -> MIL | U14: ='Gen CP'!$C15 -> MIL | W14: ='Gen CP'!$C15 -> MIL | Y14: 7:20-8:10 | AA14: HGP | AC14: ='Gen CP'!$D15 -> Oral Com | AE14: ='Gen CP'!$D15 -> Oral Com | AG14: ='Gen CP'!$D15 -> Oral Com | AI14: ='Gen CP'!$D15 -> Oral Com | AK14: 7:20-8:10 | AM14: HGP | AO14: ='Gen CP'!$E15 -> UCSP | AQ14: ='Gen CP'!$E15 -> UCSP | AS14: ='Gen CP'!$E15 -> UCSP | AU14: ='Gen CP'!$E15 -> UCSP | AW14: 7:20-8:10 | AY14: HGP | BA14: ='Gen CP'!$F15 -> Kom Pan | BC14: ='Gen CP'!$F15 -> Kom Pan | BE14: ='Gen CP'!$F15 -> Kom Pan | BG14: ='Gen CP'!$F15 -> Kom Pan | BI14: 7:20-8:10 | BK14: HGP | BM14: ='Gen CP'!$G15 -> UCSP | BO14: ='Gen CP'!$G15 -> UCSP | BQ14: ='Gen CP'!$G15 -> UCSP | BS14: ='Gen CP'!$G15 -> UCSP | BU14: 7:20-8:10 | BW14: HGP | BY14: ='Gen CP'!$H15 -> Agri-Crops NC II | CA14: ='Gen CP'!$H15 -> Agri-Crops NC II | CC14: ='Gen CP'!$H15 -> Agri-Crops NC II | CE14: ='Gen CP'!$H15 -> Agri-Crops NC II | CG14: 7:20-8:10 | CI14: HGP | CK14: ='Gen CP'!$I15 -> Earth & Life | CM14: ='Gen CP'!$I15 -> Earth & Life | CO14: ='Gen CP'!$I15 -> Earth & Life | CQ14: ='Gen CP'!$I15 -> Earth & Life | CS14: 7:20-8:10 | CU14: HGP | CW14: ='Gen CP'!$J15 -> Emp Tech | CY14: ='Gen CP'!$J15 -> Emp Tech | DA14: ='Gen CP'!$J15 -> Emp Tech | DC14: ='Gen CP'!$J15 -> Emp Tech | DE14: 7:20-8:10 | DG14: HGP | DI14: ='Gen CP'!$K15 -> UCSP | DK14: ='Gen CP'!$K15 -> UCSP | DM14: ='Gen CP'!$K15 -> UCSP | DO14: ='Gen CP'!$K15 -> UCSP | DQ14: 7:20-8:10 | DS14: HGP | DU14: ='Gen CP'!$L15 -> Food and Beverage | DW14: ='Gen CP'!$L15 -> Food and Beverage | DY14: ='Gen CP'!$L15 -> Food and Beverage | EA14: ='Gen CP'!$L15 -> Food and Beverage | EC14: 7:30-8:30 | EE14: ='Gen CP'!$M15 -> 0 | EG14: ='Gen CP'!$M15 -> 0 | EI14: ='Gen CP'!$M15 -> 0 | EK14: ='Gen CP'!$M15 -> 0 | EM14: ='Gen CP'!$M15 -> 0 | EO14: 7:30-8:30 | EP14: 60 | FA14: 7:30-8:30 | FB14: 60 | FM14: 7:30-8:30 | FN14: 60 | FY14: 7:30-8:30 | GA14: ='Gen CP'!$N15 -> 0 | GC14: ='Gen CP'!$N15 -> 0 | GE14: ='Gen CP'!$N15 -> 0 | GG14: ='Gen CP'!$N15 -> 0 | GI14: ='Gen CP'!$N15 -> 0
C15: ='Gen CP'!$B16 -> Hierco M | E15: ='Gen CP'!$B16 -> Hierco M | G15: ='Gen CP'!$B16 -> Hierco M | I15: ='Gen CP'!$B16 -> Hierco M | K15: ='Gen CP'!$B16 -> Hierco M | O15: ='Gen CP'!$C16 -> Coronel R | Q15: ='Gen CP'!$C16 -> Coronel R | S15: ='Gen CP'!$C16 -> Coronel R | U15: ='Gen CP'!$C16 -> Coronel R | W15: ='Gen CP'!$C16 -> Coronel R | AA15: ='Gen CP'!$D16 -> Sagnip M | AC15: ='Gen CP'!$D16 -> Sagnip M | AE15: ='Gen CP'!$D16 -> Sagnip M | AG15: ='Gen CP'!$D16 -> Sagnip M | AI15: ='Gen CP'!$D16 -> Sagnip M | AM15: ='Gen CP'!$E16 -> Estrella R | AO15: ='Gen CP'!$E16 -> Estrella R | AQ15: ='Gen CP'!$E16 -> Estrella R | AS15: ='Gen CP'!$E16 -> Estrella R | AU15: ='Gen CP'!$E16 -> Estrella R | AY15: ='Gen CP'!$F16 -> Aguilar EM | BA15: ='Gen CP'!$F16 -> Aguilar EM | BC15: ='Gen CP'!$F16 -> Aguilar EM | BE15: ='Gen CP'!$F16 -> Aguilar EM | BG15: ='Gen CP'!$F16 -> Aguilar EM | BK15: ='Gen CP'!$G16 -> Mamaid MC | BM15: ='Gen CP'!$G16 -> Mamaid MC | BO15: ='Gen CP'!$G16 -> Mamaid MC | BQ15: ='Gen CP'!$G16 -> Mamaid MC | BS15: ='Gen CP'!$G16 -> Mamaid MC | BW15: ='Gen CP'!$H16 -> Reyes D | BY15: ='Gen CP'!$H16 -> Reyes D | CA15: ='Gen CP'!$H16 -> Reyes D | CC15: ='Gen CP'!$H16 -> Reyes D | CE15: ='Gen CP'!$H16 -> Reyes D | CI15: ='Gen CP'!$I16 -> Almazan AD | CK15: ='Gen CP'!$I16 -> Almazan AD | CM15: ='Gen CP'!$I16 -> Almazan AD | CO15: ='Gen CP'!$I16 -> Almazan AD | CQ15: ='Gen CP'!$I16 -> Almazan AD | CU15: ='Gen CP'!$J16 -> Guerrero LG | CW15: ='Gen CP'!$J16 -> Guerrero LG | CY15: ='Gen CP'!$J16 -> Guerrero LG | DA15: ='Gen CP'!$J16 -> Guerrero LG | DC15: ='Gen CP'!$J16 -> Guerrero LG | DG15: ='Gen CP'!$K16 -> Valdez R | DI15: ='Gen CP'!$K16 -> Valdez R | DK15: ='Gen CP'!$K16 -> Valdez R | DM15: ='Gen CP'!$K16 -> Valdez R | DO15: ='Gen CP'!$K16 -> Valdez R | DS15: ='Gen CP'!$L16 -> Maniquiz T | DU15: ='Gen CP'!$L16 -> Maniquiz T | DW15: ='Gen CP'!$L16 -> Maniquiz T | DY15: ='Gen CP'!$L16 -> Maniquiz T | EA15: ='Gen CP'!$L16 -> Maniquiz T | EE15: ='Gen CP'!$M16 -> 0 | EG15: ='Gen CP'!$M16 -> 0 | EI15: ='Gen CP'!$M16 -> 0 | EK15: ='Gen CP'!$M16 -> 0 | EM15: ='Gen CP'!$M16 -> 0 | GA15: ='Gen CP'!$N16 -> Crisostomo R | GC15: ='Gen CP'!$N16 -> Crisostomo R | GE15: ='Gen CP'!$N16 -> Crisostomo R | GG15: ='Gen CP'!$N16 -> Crisostomo R | GI15: ='Gen CP'!$N16 -> Crisostomo R
A17: 8:10-9:00 | C17: ='Gen CP'!$B17 -> Pre-Calculus | E17: ='Gen CP'!$B17 -> Pre-Calculus | G17: ='Gen CP'!$B17 -> Pre-Calculus | I17: ='Gen CP'!$B17 -> Pre-Calculus | K17: Pre-Calculus | M17: 8:10-9:00 | O17: ='Gen CP'!$C17 -> Kom Pan | Q17: ='Gen CP'!$C17 -> Kom Pan | S17: ='Gen CP'!$C17 -> Kom Pan | U17: ='Gen CP'!$C17 -> Kom Pan | W17: ='Gen CP'!$C17 -> Kom Pan | Y17: 8:10-9:00 | AA17: ='Gen CP'!$D17 -> UCSP | AC17: ='Gen CP'!$D17 -> UCSP | AE17: P.E. | AG17: ='Gen CP'!$D17 -> UCSP | AI17: ='Gen CP'!$D17 -> UCSP | AK17: 8:10-9:00 | AM17: ='Gen CP'!$E17 -> Oral Com | AO17: ='Gen CP'!$E17 -> Oral Com | AQ17: ='Gen CP'!$E17 -> Oral Com | AS17: ='Gen CP'!$E17 -> Oral Com | AU17: ='Gen CP'!$E17 -> Oral Com | AW17: 8:10-9:00 | AY17: ='Gen CP'!$F17 -> 21st Cen Lit | BA17: ='Gen CP'!$F17 -> 21st Cen Lit | BC17: ='Gen CP'!$F17 -> 21st Cen Lit | BE17: ='Gen CP'!$F17 -> 21st Cen Lit | BG17: ='Gen CP'!$F17 -> 21st Cen Lit | BI17: 8:10-9:00 | BK17: ='Gen CP'!$G17 -> Earth & Life | BM17: ='Gen CP'!$G17 -> Earth & Life | BO17: ='Gen CP'!$G17 -> Earth & Life | BQ17: ='Gen CP'!$G17 -> Earth & Life | BS17: ='Gen CP'!$G17 -> Earth & Life | BU17: 8:10-9:10 | BW17: ='Gen CP'!$H17 -> Agri-Crops NC II | BY17: ='Gen CP'!$H17 -> Agri-Crops NC II | CA17: ='Gen CP'!$H17 -> Agri-Crops NC II | CC17: ='Gen CP'!$H17 -> Agri-Crops NC II | CE17: ='Gen CP'!$H17 -> Agri-Crops NC II | CG17: 8:10-9:00 8:40-9:30 | CI17: ='Gen CP'!$I17 -> Oral Com | CK17: ='Gen CP'!$I17 -> Oral Com | CM17: ='Gen CP'!$I17 -> Oral Com | CO17: P.E. | CQ17: ='Gen CP'!$I17 -> Oral Com | CS17: 8:10-9:00 | CU17: ='Gen CP'!$J17 -> Gen Math | CW17: ='Gen CP'!$J17 -> Gen Math | CY17: ='Gen CP'!$J17 -> Gen Math | DA17: ='Gen CP'!$J17 -> Gen Math | DC17: ='Gen CP'!$J17 -> Gen Math | DE17: 8:10-9:00 | DG17: ='Gen CP'!$K17 -> Earth & Life | DI17: ='Gen CP'!$K17 -> Earth & Life | DK17: ='Gen CP'!$K17 -> Earth & Life | DM17: ='Gen CP'!$K17 -> Earth & Life | DO17: ='Gen CP'!$K17 -> Earth & Life | DQ17: 8:10-9:00 | DS17: ='Gen CP'!$L17 -> Food and Beverage | DU17: P.E. | DW17: ='Gen CP'!$L17 -> Food and Beverage | DY17: ='Gen CP'!$L17 -> Food and Beverage | EA17: ='Gen CP'!$L17 -> Food and Beverage | EC17: 8:30-9:30 | EE17: ='Gen CP'!$M17 -> 0 | EG17: ='Gen CP'!$M17 -> 0 | EI17: ='Gen CP'!$M17 -> 0 | EK17: ='Gen CP'!$M17 -> 0 | EM17: ='Gen CP'!$M17 -> 0 | EO17: 8:30-9:30 | EP17: 60 | FA17: 8:30-9:30 | FB17: 60 | FM17: 8:30-9:30 | FN17: 60 | FY17: 8:30-9:30 | GA17: ='Gen CP'!$N17 -> 0 | GC17: ='Gen CP'!$N17 -> 0 | GE17: ='Gen CP'!$N17 -> 0 | GG17: ='Gen CP'!$N17 -> 0 | GI17: ='Gen CP'!$N17 -> 0
C18: ='Gen CP'!$B18 -> Lorenzana C | E18: ='Gen CP'!$B18 -> Lorenzana C | G18: ='Gen CP'!$B18 -> Lorenzana C | I18: ='Gen CP'!$B18 -> Lorenzana C | K18: C.Lorenzana | O18: ='Gen CP'!$C18 -> Aguilar EM | Q18: ='Gen CP'!$C18 -> Aguilar EM | S18: ='Gen CP'!$C18 -> Aguilar EM | U18: ='Gen CP'!$C18 -> Aguilar EM | W18: ='Gen CP'!$C18 -> Aguilar EM | AA18: ='Gen CP'!$D18 -> Estrella R | AC18: ='Gen CP'!$D18 -> Estrella R | AE18: Gurrero LG | AG18: ='Gen CP'!$D18 -> Estrella R | AI18: ='Gen CP'!$D18 -> Estrella R | AM18: ='Gen CP'!$E18 -> Sagnip M | AO18: ='Gen CP'!$E18 -> Sagnip M | AQ18: ='Gen CP'!$E18 -> Sagnip M | AS18: ='Gen CP'!$E18 -> Sagnip M | AU18: ='Gen CP'!$E18 -> Sagnip M | AY18: ='Gen CP'!$F18 -> Crisostomo R | BA18: ='Gen CP'!$F18 -> Crisostomo R | BC18: ='Gen CP'!$F18 -> Crisostomo R | BE18: ='Gen CP'!$F18 -> Crisostomo R | BG18: ='Gen CP'!$F18 -> Crisostomo R | BK18: ='Gen CP'!$G18 -> Almazan AD | BM18: ='Gen CP'!$G18 -> Almazan AD | BO18: ='Gen CP'!$G18 -> Almazan AD | BQ18: ='Gen CP'!$G18 -> Almazan AD | BS18: ='Gen CP'!$G18 -> Almazan AD | BW18: ='Gen CP'!$H18 -> Reyes D | BY18: ='Gen CP'!$H18 -> Reyes D | CA18: ='Gen CP'!$H18 -> Reyes D | CC18: ='Gen CP'!$H18 -> Reyes D | CE18: ='Gen CP'!$H18 -> Reyes D | CI18: ='Gen CP'!$I18 -> Tamondong A | CK18: ='Gen CP'!$I18 -> Tamondong A | CM18: ='Gen CP'!$I18 -> Tamondong A | CO18: Guerrero LG | CQ18: ='Gen CP'!$I18 -> Tamondong A | CU18: ='Gen CP'!$J18 -> Domingo V | CW18: ='Gen CP'!$J18 -> Domingo V | CY18: ='Gen CP'!$J18 -> Domingo V | DA18: ='Gen CP'!$J18 -> Domingo V | DC18: ='Gen CP'!$J18 -> Domingo V | DG18: ='Gen CP'!$K18 -> Marcelo OJ | DI18: ='Gen CP'!$K18 -> Marcelo OJ | DK18: ='Gen CP'!$K18 -> Marcelo OJ | DM18: ='Gen CP'!$K18 -> Marcelo OJ | DO18: ='Gen CP'!$K18 -> Marcelo OJ | DS18: ='Gen CP'!$L18 -> Maniquiz T | DU18: Guerrero LG | DW18: ='Gen CP'!$L18 -> Maniquiz T | DY18: ='Gen CP'!$L18 -> Maniquiz T | EA18: ='Gen CP'!$L18 -> Maniquiz T | EE18: ='Gen CP'!$M18 -> 0 | EG18: ='Gen CP'!$M18 -> 0 | EI18: ='Gen CP'!$M18 -> 0 | EK18: ='Gen CP'!$M18 -> 0 | EM18: ='Gen CP'!$M18 -> 0 | GA18: ='Gen CP'!$N18 -> Bartolome H | GC18: ='Gen CP'!$N18 -> Bartolome H | GE18: ='Gen CP'!$N18 -> Bartolome H | GG18: ='Gen CP'!$N18 -> Bartolome H | GI18: ='Gen CP'!$N18 -> Bartolome H
A19: 9:00-9:30 | B19: RECESS | M19: 9:00-9:30 | N19: RECESS | Y19: 9:00-9:30 | Z19: RECESS | AK19: 9:00-9:30 | AL19: RECESS | AW19: 9:00-9:30 | AX19: RECESS | BI19: 9:00-9:30 | BJ19: RECESS | BU19: 9:00-9:30 | BV19: RECESS | CG19: 9:00-9:30 | CH19: RECESS | CS19: 9:00-9:30 | CT19: RECESS | DE19: 9:00-9:30 | DF19: RECESS | DQ19: 9:00-9:30 | DR19: RECESS | EC19: 9:00-9:30 | ED19: RECESS | EO19: RECESS | FA19: RECESS | FM19: RECESS | FY19: RECESS
A20: 9:30-10:20 | C20: ='Gen CP'!$B20 -> Gen Math | E20: ='Gen CP'!$B20 -> Gen Math | G20: ='Gen CP'!$B20 -> Gen Math | I20: ='Gen CP'!$B20 -> Gen Math | K20: P.E. | M20: 9:30-10:20 | O20: ='Gen CP'!$C20 -> 21st Cen Lit | Q20: ='Gen CP'!$C20 -> 21st Cen Lit | S20: ='Gen CP'!$C20 -> 21st Cen Lit | U20: ='Gen CP'!$C20 -> 21st Cen Lit | W20: ='Gen CP'!$C20 -> 21st Cen Lit | Y20: 9:30-10:20 | AA20: ='Gen CP'!$D20 -> Kom Pan | AC20: Vacant | AE20: ='Gen CP'!$D20 -> Kom Pan | AG20: ='Gen CP'!$D20 -> Kom Pan | AI20: ='Gen CP'!$D20 -> Kom Pan | AK20: 9:30-10:20 | AM20: ='Gen CP'!$E20 -> Earth & Life | AO20: ='Gen CP'!$E20 -> Earth & Life | AQ20: P.E. | AS20: ='Gen CP'!$E20 -> Earth & Life | AU20: ='Gen CP'!$E20 -> Earth & Life | AW20: 9:30-10:20 | AY20: ='Gen CP'!$F20 -> Oral Com | BA20: ='Gen CP'!$F20 -> Oral Com | BC20: ='Gen CP'!$F20 -> Oral Com | BE20: ='Gen CP'!$F20 -> Oral Com | BG20: ='Gen CP'!$F20 -> Oral Com | BI20: 9:30-10:20 | BK20: ='Gen CP'!$G20 -> MIL | BM20: ='Gen CP'!$G20 -> MIL | BO20: ='Gen CP'!$G20 -> MIL | BQ20: ='Gen CP'!$G20 -> MIL | BS20: ='Gen CP'!$G20 -> MIL | BU20: 9:30-10:20 | BW20: ='Gen CP'!$H20 -> UCSP | BY20: ='Gen CP'!$H20 -> UCSP | CA20: ='Gen CP'!$H20 -> UCSP | CC20: ='Gen CP'!$H20 -> UCSP | CE20: ='Gen CP'!$H20 -> UCSP | CG20: 9:30-10:20 | CI20: ='Gen CP'!$I20 -> SMAW NC I | CK20: ='Gen CP'!$I20 -> SMAW NC I | CM20: ='Gen CP'!$I20 -> SMAW NC I | CO20: ='Gen CP'!$I20 -> SMAW NC I | CQ20: ='Gen CP'!$I20 -> SMAW NC I | CS20: 9:30-10:20 | CU20: ='Gen CP'!$J20 -> CSS | CW20: ='Gen CP'!$J20 -> CSS | CY20: ='Gen CP'!$J20 -> CSS | DA20: ='Gen CP'!$J20 -> CSS | DC20: ='Gen CP'!$J20 -> CSS | DE20: 9:20-10:20 9:30-10:20 | DG20: ='Gen CP'!$K20 -> Gen Math | DI20: ='Gen CP'!$K20 -> Gen Math | DK20: ='Gen CP'!$K20 -> Gen Math | DM20: ='Gen CP'!$K20 -> Gen Math | DO20: ='Gen CP'!$K20 -> Gen Math | DQ20: 9:30-10:20 | DS20: ='Gen CP'!$L20 -> Earth & Life | DU20: ='Gen CP'!$L20 -> Earth & Life | DW20: ='Gen CP'!$L20 -> Earth & Life | DY20: ='Gen CP'!$L20 -> Earth & Life | EA20: ='Gen CP'!$L20 -> Earth & Life | EC20: 10:00-11:00 | EE20: ='Gen CP'!$M20 -> 0 | EG20: ='Gen CP'!$M20 -> 0 | EI20: ='Gen CP'!$M20 -> 0 | EK20: ='Gen CP'!$M20 -> 0 | EM20: ='Gen CP'!$M20 -> 0 | EO20: 10:00-11:00 | EP20: 60 | FA20: 10:00-11:00 | FB20: 60 | FM20: 10:00-11:00 | FN20: 60 | FY20: 10:00-11:00
C21: ='Gen CP'!$B21 -> Lorenzana C | E21: ='Gen CP'!$B21 -> Lorenzana C | G21: ='Gen CP'!$B21 -> Lorenzana C | I21: ='Gen CP'!$B21 -> Lorenzana C | K21: Gurrero LG | O21: ='Gen CP'!$C21 -> Crisostomo R | Q21: ='Gen CP'!$C21 -> Crisostomo R | S21: ='Gen CP'!$C21 -> Crisostomo R | U21: ='Gen CP'!$C21 -> Crisostomo R | W21: ='Gen CP'!$C21 -> Crisostomo R | AA21: ='Gen CP'!$D21 -> Aguilar EM | AE21: ='Gen CP'!$D21 -> Aguilar EM | AG21: ='Gen CP'!$D21 -> Aguilar EM | AI21: ='Gen CP'!$D21 -> Aguilar EM | AM21: ='Gen CP'!$E21 -> Almazan AD | AO21: ='Gen CP'!$E21 -> Almazan AD | AQ21: Gurrero LG | AS21: ='Gen CP'!$E21 -> Almazan AD | AU21: ='Gen CP'!$E21 -> Almazan AD | AY21: ='Gen CP'!$F21 -> Sagnip M | BA21: ='Gen CP'!$F21 -> Sagnip M | BC21: ='Gen CP'!$F21 -> Sagnip M | BE21: ='Gen CP'!$F21 -> Sagnip M | BG21: ='Gen CP'!$F21 -> Sagnip M | BK21: ='Gen CP'!$G21 -> Coronel R | BM21: ='Gen CP'!$G21 -> Coronel R | BO21: ='Gen CP'!$G21 -> Coronel R | BQ21: ='Gen CP'!$G21 -> Coronel R | BS21: ='Gen CP'!$G21 -> Coronel R | BW21: ='Gen CP'!$H21 -> Estrella R | BY21: ='Gen CP'!$H21 -> Estrella R | CA21: ='Gen CP'!$H21 -> Estrella R | CC21: ='Gen CP'!$H21 -> Estrella R | CE21: ='Gen CP'!$H21 -> Estrella R | CI21: ='Gen CP'!$I21 -> Sarmiento F | CK21: ='Gen CP'!$I21 -> Sarmiento F | CM21: ='Gen CP'!$I21 -> Sarmiento F | CO21: ='Gen CP'!$I21 -> Sarmiento F | CQ21: ='Gen CP'!$I21 -> Sarmiento F | CU21: ='Gen CP'!$J21 -> Mercado R | CW21: ='Gen CP'!$J21 -> Mercado R | CY21: ='Gen CP'!$J21 -> Mercado R | DA21: ='Gen CP'!$J21 -> Mercado R | DC21: ='Gen CP'!$J21 -> Mercado R | DG21: ='Gen CP'!$K21 -> Domingo V | DI21: ='Gen CP'!$K21 -> Domingo V | DK21: ='Gen CP'!$K21 -> Domingo V | DM21: ='Gen CP'!$K21 -> Domingo V | DO21: ='Gen CP'!$K21 -> Domingo V | DS21: ='Gen CP'!$L21 -> Marcelo OJ | DU21: ='Gen CP'!$L21 -> Marcelo OJ | DW21: ='Gen CP'!$L21 -> Marcelo OJ | DY21: ='Gen CP'!$L21 -> Marcelo OJ | EA21: ='Gen CP'!$L21 -> Marcelo OJ | EE21: ='Gen CP'!$M21 -> 0 | EG21: ='Gen CP'!$M21 -> 0 | EI21: ='Gen CP'!$M21 -> 0 | EK21: ='Gen CP'!$M21 -> 0 | EM21: ='Gen CP'!$M21 -> 0
A22: 10:20-11:10 | C22: ='Gen CP'!$B22 -> UCSP | E22: ='Gen CP'!$B22 -> UCSP | G22: ='Gen CP'!$B22 -> UCSP | I22: ='Gen CP'!$B22 -> UCSP | K22: ='Gen CP'!$B22 -> UCSP | M22: 10:20-11:10 | O22: ='Gen CP'!$C22 -> Gen Math | Q22: ='Gen CP'!$C22 -> Gen Math | S22: ='Gen CP'!$C22 -> Gen Math | U22: ='Gen CP'!$C22 -> Gen Math | W22: P.E. | Y22: 10:20-11:10 | AA22: ='Gen CP'!$D22 -> 21st Cen Lit | AC22: ='Gen CP'!$D22 -> 21st Cen Lit | AE22: ='Gen CP'!$D22 -> 21st Cen Lit | AG22: ='Gen CP'!$D22 -> 21st Cen Lit | AI22: ='Gen CP'!$D22 -> 21st Cen Lit | AK22: 10:20-11:10 | AM22: ='Gen CP'!$E22 -> MIL | AO22: ='Gen CP'!$E22 -> MIL | AQ22: ='Gen CP'!$E22 -> MIL | AS22: ='Gen CP'!$E22 -> MIL | AU22: ='Gen CP'!$E22 -> MIL | AW22: 10:20-11:10 | AY22: ='Gen CP'!$F22 -> Gen Math | BA22: ='Gen CP'!$F22 -> Gen Math | BC22: P.E. | BE22: ='Gen CP'!$F22 -> Gen Math | BG22: ='Gen CP'!$F22 -> Gen Math | BI22: 10:20-11:10 | BK22: ='Gen CP'!$G22 -> Emp Tech | BM22: ='Gen CP'!$G22 -> Emp Tech | BO22: ='Gen CP'!$G22 -> Emp Tech | BQ22: ='Gen CP'!$G22 -> Emp Tech | BS22: ='Gen CP'!$G22 -> Emp Tech | BU22: 10:20-11:10 | BW22: ='Gen CP'!$H22 -> Earth & Life | BY22: P.E. | CA22: ='Gen CP'!$H22 -> Earth & Life | CC22: ='Gen CP'!$H22 -> Earth & Life | CE22: ='Gen CP'!$H22 -> Earth & Life | CG22: 10:20-11:10 | CI22: ='Gen CP'!$I22 -> SMAW NC I | CK22: ='Gen CP'!$I22 -> SMAW NC I | CM22: ='Gen CP'!$I22 -> SMAW NC I | CO22: ='Gen CP'!$I22 -> SMAW NC I | CQ22: ='Gen CP'!$I22 -> SMAW NC I | CS22: 10:20-11:10 10:20-11:20 | CU22: ='Gen CP'!$J22 -> CSS | CW22: ='Gen CP'!$J22 -> CSS | CY22: ='Gen CP'!$J22 -> CSS | DA22: ='Gen CP'!$J22 -> CSS | DC22: ='Gen CP'!$J22 -> CSS | DE22: 10:20-11:10 | DG22: ='Gen CP'!$K22 -> Kom Pan | DI22: ='Gen CP'!$K22 -> Kom Pan | DK22: ='Gen CP'!$K22 -> Kom Pan | DM22: P.E. | DO22: ='Gen CP'!$K22 -> Kom Pan | DQ22: 10:20-11:10 | DS22: ='Gen CP'!$L22 -> Oral Com | DU22: ='Gen CP'!$L22 -> Oral Com | DW22: ='Gen CP'!$L22 -> Oral Com | DY22: ='Gen CP'!$L22 -> Oral Com | EA22: ='Gen CP'!$L22 -> Oral Com | EC22: 11:00-12:00 | EE22: ='Gen CP'!$M22 -> 0 | EG22: ='Gen CP'!$M22 -> 0 | EI22: ='Gen CP'!$M22 -> 0 | EK22: ='Gen CP'!$M22 -> 0 | EM22: ='Gen CP'!$M22 -> 0 | EO22: 11:00-12:00 | EP22: 60 | FA22: 11:00-12:00 | FB22: 60 | FM22: 11:00-12:00 | FN22: 60 | FY22: 11:00-12:00
C23: ='Gen CP'!$B23 -> Estrella R | E23: ='Gen CP'!$B23 -> Estrella R | G23: ='Gen CP'!$B23 -> Estrella R | I23: ='Gen CP'!$B23 -> Estrella R | K23: ='Gen CP'!$B23 -> Estrella R | O23: ='Gen CP'!$C23 -> Lorenzana C | Q23: ='Gen CP'!$C23 -> Lorenzana C | S23: ='Gen CP'!$C23 -> Lorenzana C | U23: ='Gen CP'!$C23 -> Lorenzana C | W23: Guerrero LG | AA23: ='Gen CP'!$D23 -> Crisostomo R | AC23: ='Gen CP'!$D23 -> Crisostomo R | AE23: ='Gen CP'!$D23 -> Crisostomo R | AG23: ='Gen CP'!$D23 -> Crisostomo R | AI23: ='Gen CP'!$D23 -> Crisostomo R | AM23: ='Gen CP'!$E23 -> Coronel R | AO23: ='Gen CP'!$E23 -> Coronel R | AQ23: ='Gen CP'!$E23 -> Coronel R | AS23: ='Gen CP'!$E23 -> Coronel R | AU23: ='Gen CP'!$E23 -> Coronel R | AY23: ='Gen CP'!$F23 -> Domingo V | BA23: ='Gen CP'!$F23 -> Domingo V | BC23: Guerrero LG | BE23: ='Gen CP'!$F23 -> Domingo V | BG23: ='Gen CP'!$F23 -> Domingo V | BK23: ='Gen CP'!$G23 -> Reyes D | BM23: ='Gen CP'!$G23 -> Reyes D | BO23: ='Gen CP'!$G23 -> Reyes D | BQ23: ='Gen CP'!$G23 -> Reyes D | BS23: ='Gen CP'!$G23 -> Reyes D | BW23: ='Gen CP'!$H23 -> Almazan AD | BY23: Guerrero LG | CA23: ='Gen CP'!$H23 -> Almazan AD | CC23: ='Gen CP'!$H23 -> Almazan AD | CE23: ='Gen CP'!$H23 -> Almazan AD | CI23: ='Gen CP'!$I23 -> Sarmiento F | CK23: ='Gen CP'!$I23 -> Sarmiento F | CM23: ='Gen CP'!$I23 -> Sarmiento F | CO23: ='Gen CP'!$I23 -> Sarmiento F | CQ23: ='Gen CP'!$I23 -> Sarmiento F | CU23: ='Gen CP'!$J23 -> Mercado R | CW23: ='Gen CP'!$J23 -> Mercado R | CY23: ='Gen CP'!$J23 -> Mercado R | DA23: ='Gen CP'!$J23 -> Mercado R | DC23: ='Gen CP'!$J23 -> Mercado R | DG23: ='Gen CP'!$K23 -> Aguilar EM | DI23: ='Gen CP'!$K23 -> Aguilar EM | DK23: ='Gen CP'!$K23 -> Aguilar EM | DM23: Guerrero LG | DO23: ='Gen CP'!$K23 -> Aguilar EM | DS23: ='Gen CP'!$L23 -> Sagnip M | DU23: ='Gen CP'!$L23 -> Sagnip M | DW23: ='Gen CP'!$L23 -> Sagnip M | DY23: ='Gen CP'!$L23 -> Sagnip M | EA23: ='Gen CP'!$L23 -> Sagnip M | EE23: ='Gen CP'!$M23 -> 0 | EG23: ='Gen CP'!$M23 -> 0 | EI23: ='Gen CP'!$M23 -> 0 | EK23: ='Gen CP'!$M23 -> 0 | EM23: ='Gen CP'!$M23 -> 0
A24: 11:10-12:00 | C24: ='Gen CP'!$B24 -> Chemistry 1 | E24: ='Gen CP'!$B24 -> Chemistry 1 | G24: ='Gen CP'!$B24 -> Chemistry 1 | I24: ='Gen CP'!$B24 -> Chemistry 1 | K24: ='Gen CP'!$B24 -> Chemistry 1 | M24: 11:10-12:00 | O24: ='Gen CP'!$C24 -> UCSP | Q24: ='Gen CP'!$C24 -> UCSP | S24: ='Gen CP'!$C24 -> UCSP | U24: ='Gen CP'!$C24 -> UCSP | W24: ='Gen CP'!$C24 -> UCSP | Y24: 11:10-12:00 | AA24: ='Gen CP'!$D24 -> Emp Tech | AC24: ='Gen CP'!$D24 -> Emp Tech | AE24: ='Gen CP'!$D24 -> Emp Tech | AG24: ='Gen CP'!$D24 -> Emp Tech | AI24: ='Gen CP'!$D24 -> Emp Tech | AK24: 11:10-12:00 | AM24: ='Gen CP'!$E24 -> 21st Cen Lit | AO24: ='Gen CP'!$E24 -> 21st Cen Lit | AQ24: ='Gen CP'!$E24 -> 21st Cen Lit | AS24: ='Gen CP'!$E24 -> 21st Cen Lit | AU24: ='Gen CP'!$E24 -> 21st Cen Lit | AW24: 11:10-12:00 | AY24: ='Gen CP'!$F24 -> Earth & Life | BA24: ='Gen CP'!$F24 -> Earth & Life | BC24: ='Gen CP'!$F24 -> Earth & Life | BE24: ='Gen CP'!$F24 -> Earth & Life | BG24: ='Gen CP'!$F24 -> Earth & Life | BI24: 11:10-12:00 | BK24: ='Gen CP'!$G24 -> Oral Com | BM24: P.E. | BO24: ='Gen CP'!$G24 -> Oral Com | BQ24: ='Gen CP'!$G24 -> Oral Com | BS24: ='Gen CP'!$G24 -> Oral Com | BU24: 11:10-12:00 | BW24: ='Gen CP'!$H24 -> Gen Math | BY24: ='Gen CP'!$H24 -> Gen Math | CA24: ='Gen CP'!$H24 -> Gen Math | CC24: ='Gen CP'!$H24 -> Gen Math | CE24: ='Gen CP'!$H24 -> Gen Math | CG24: 11:10-12:00 | CI24: ='Gen CP'!$I24 -> Kom Pan | CK24: ='Gen CP'!$I24 -> Kom Pan | CM24: ='Gen CP'!$I24 -> Kom Pan | CO24: ='Gen CP'!$I24 -> Kom Pan | CQ24: ='Gen CP'!$I24 -> Kom Pan | CS24: 11:10-12:00 | CU24: ='Gen CP'!$J24 -> Oral Com | CW24: ='Gen CP'!$J24 -> Oral Com | CY24: ='Gen CP'!$J24 -> Oral Com | DA24: P.E. | DC24: ='Gen CP'!$J24 -> Oral Com | DE24: 11:10-12:00 | DG24: ='Gen CP'!$K24 -> Creative Writing | DI24: ='Gen CP'!$K24 -> Creative Writing | DK24: ='Gen CP'!$K24 -> Creative Writing | DM24: ='Gen CP'!$K24 -> Creative Writing | DO24: ='Gen CP'!$K24 -> Creative Writing | DQ24: 11:10-12:00 | DS24: ='Gen CP'!$L24 -> Gen Math | DU24: ='Gen CP'!$L24 -> Gen Math | DW24: ='Gen CP'!$L24 -> Gen Math | DY24: ='Gen CP'!$L24 -> Gen Math | EA24: ='Gen CP'!$L24 -> Gen Math | EC24: 1:00 -2:00 | EE24: ='Gen CP'!$M24 -> 0 | EG24: ='Gen CP'!$M24 -> 0 | EI24: ='Gen CP'!$M24 -> 0 | EK24: ='Gen CP'!$M24 -> 0 | EM24: ='Gen CP'!$M24 -> 0 | EO24: 1:00 -2:00 | EP24: 60 | FA24: 1:00 -2:00 | FB24: 60 | FM24: 1:00 -2:00 | FN24: 60 | FY24: 1:00 -2:00
C25: ='Gen CP'!$B25 -> Orgil E | E25: ='Gen CP'!$B25 -> Orgil E | G25: ='Gen CP'!$B25 -> Orgil E | I25: ='Gen CP'!$B25 -> Orgil E | K25: ='Gen CP'!$B25 -> Orgil E | O25: ='Gen CP'!$C25 -> Estrella R | Q25: ='Gen CP'!$C25 -> Estrella R | S25: ='Gen CP'!$C25 -> Estrella R | U25: ='Gen CP'!$C25 -> Estrella R | W25: ='Gen CP'!$C25 -> Estrella R | AA25: ='Gen CP'!$D25 -> Reyes D | AC25: ='Gen CP'!$D25 -> Reyes D | AE25: ='Gen CP'!$D25 -> Reyes D | AG25: ='Gen CP'!$D25 -> Reyes D | AI25: ='Gen CP'!$D25 -> Reyes D | AM25: ='Gen CP'!$E25 -> Crisostomo R | AO25: ='Gen CP'!$E25 -> Crisostomo R | AQ25: ='Gen CP'!$E25 -> Crisostomo R | AS25: ='Gen CP'!$E25 -> Crisostomo R | AU25: ='Gen CP'!$E25 -> Crisostomo R | AY25: ='Gen CP'!$F25 -> Marcelo OJ | BA25: ='Gen CP'!$F25 -> Marcelo OJ | BC25: ='Gen CP'!$F25 -> Marcelo OJ | BE25: ='Gen CP'!$F25 -> Marcelo OJ | BG25: ='Gen CP'!$F25 -> Marcelo OJ | BK25: ='Gen CP'!$G25 -> Sagnip M | BM25: Guerrero LG | BO25: ='Gen CP'!$G25 -> Sagnip M | BQ25: ='Gen CP'!$G25 -> Sagnip M | BS25: ='Gen CP'!$G25 -> Sagnip M | BW25: ='Gen CP'!$H25 -> Domingo V | BY25: ='Gen CP'!$H25 -> Domingo V | CA25: ='Gen CP'!$H25 -> Domingo V | CC25: ='Gen CP'!$H25 -> Domingo V | CE25: ='Gen CP'!$H25 -> Domingo V | CI25: ='Gen CP'!$I25 -> Pascua I | CK25: ='Gen CP'!$I25 -> Pascua I | CM25: ='Gen CP'!$I25 -> Pascua I | CO25: ='Gen CP'!$I25 -> Pascua I | CQ25: ='Gen CP'!$I25 -> Pascua I | CU25: ='Gen CP'!$J25 -> Coronel R | CW25: ='Gen CP'!$J25 -> Coronel R | CY25: ='Gen CP'!$J25 -> Coronel R | DA25: Guerrero LG | DC25: ='Gen CP'!$J25 -> Coronel R | DG25: ='Gen CP'!$K25 -> Sarmiento F | DI25: ='Gen CP'!$K25 -> Sarmiento F | DK25: ='Gen CP'!$K25 -> Sarmiento F | DM25: ='Gen CP'!$K25 -> Sarmiento F | DO25: ='Gen CP'!$K25 -> Sarmiento F | DS25: ='Gen CP'!$L25 -> Lorenzana C | DU25: ='Gen CP'!$L25 -> Lorenzana C | DW25: ='Gen CP'!$L25 -> Lorenzana C | DY25: ='Gen CP'!$L25 -> Lorenzana C | EA25: ='Gen CP'!$L25 -> Lorenzana C | EE25: ='Gen CP'!$M25 -> 0 | EG25: ='Gen CP'!$M25 -> 0 | EI25: ='Gen CP'!$M25 -> 0 | EK25: ='Gen CP'!$M25 -> 0 | EM25: ='Gen CP'!$M25 -> 0
A26: 12:00-1:00 | B26: LUNCH | M26: 12:00-1:00 | N26: LUNCH | Y26: 12:00-1:00 | Z26: LUNCH | AK26: 12:00-1:00 | AL26: LUNCH | AW26: 12:00-1:00 | AX26: LUNCH | BI26: 12:00-1:00 | BJ26: LUNCH | BU26: 12:00-1:00 | BV26: LUNCH | CG26: 12:00-1:00 | CH26: LUNCH | CS26: 12:00-1:00 | CT26: LUNCH | DE26: 12:00-1:00 | DF26: LUNCH | DQ26: 12:00-1:00 | DR26: LUNCH | EC26: 12:00-1:00 | ED26: LUNCH
A27: 1:00-1:50 | C27: ='Gen CP'!$B27 -> Kom Pan | E27: ='Gen CP'!$B27 -> Kom Pan | G27: ='Gen CP'!$B27 -> Kom Pan | I27: ='Gen CP'!$B27 -> Kom Pan | K27: ='Gen CP'!$B27 -> Kom Pan | M27: 1:00-1:50 | O27: ='Gen CP'!$C27 -> Earth & Life | Q27: ='Gen CP'!$C27 -> Earth & Life | S27: ='Gen CP'!$C27 -> Earth & Life | U27: ='Gen CP'!$C27 -> Earth & Life | W27: ='Gen CP'!$C27 -> Earth & Life | Y27: 1:00-1:50 | AA27: ='Gen CP'!$D27 -> MIL | AC27: ='Gen CP'!$D27 -> MIL | AE27: ='Gen CP'!$D27 -> MIL | AG27: ='Gen CP'!$D27 -> MIL | AI27: ='Gen CP'!$D27 -> MIL | AK27: 1:00-1:50 | AM27: ='Gen CP'!$E27 -> Emp Tech | AO27: ='Gen CP'!$E27 -> Emp Tech | AQ27: ='Gen CP'!$E27 -> Emp Tech | AS27: ='Gen CP'!$E27 -> Emp Tech | AU27: ='Gen CP'!$E27 -> Emp Tech | AW27: 1:00-1:50 | AY27: ='Gen CP'!$F27 -> Emp Tech | BA27: ='Gen CP'!$F27 -> Emp Tech | BC27: ='Gen CP'!$F27 -> Emp Tech | BE27: ='Gen CP'!$F27 -> Emp Tech | BG27: ='Gen CP'!$F27 -> Emp Tech | BI27: 1:00-1:50 | BK27: ='Gen CP'!$G27 -> Gen Math | BM27: ='Gen CP'!$G27 -> Gen Math | BO27: ='Gen CP'!$G27 -> Gen Math | BQ27: ='Gen CP'!$G27 -> Gen Math | BS27: ='Gen CP'!$G27 -> Gen Math | BU27: 1:00-1:50 | BW27: ='Gen CP'!$H27 -> Oral Com | BY27: ='Gen CP'!$H27 -> Oral Com | CA27: ='Gen CP'!$H27 -> Oral Com | CC27: ='Gen CP'!$H27 -> Oral Com | CE27: ='Gen CP'!$H27 -> Oral Com | CG27: 1:00-1:50 | CI27: ='Gen CP'!$I27 -> Emp Tech | CK27: ='Gen CP'!$I27 -> Emp Tech | CM27: ='Gen CP'!$I27 -> Emp Tech | CO27: ='Gen CP'!$I27 -> Emp Tech | CQ27: ='Gen CP'!$I27 -> Emp Tech | CS27: 1:00-1:50 | CU27: ='Gen CP'!$J27 -> Earth & Life | CW27: ='Gen CP'!$J27 -> Earth & Life | CY27: ='Gen CP'!$J27 -> Earth & Life | DA27: ='Gen CP'!$J27 -> Earth & Life | DC27: ='Gen CP'!$J27 -> Earth & Life | DE27: 1:00-1:50 | DG27: ='Gen CP'!$K27 -> Organ Man | DI27: ='Gen CP'!$K27 -> Organ Man | DK27: ='Gen CP'!$K27 -> Organ Man | DM27: ='Gen CP'!$K27 -> Organ Man | DO27: ='Gen CP'!$K27 -> Organ Man | DQ27: 1:00-1:50 | DS27: ='Gen CP'!$L27 -> Kom Pan | DU27: ='Gen CP'!$L27 -> Kom Pan | DW27: ='Gen CP'!$L27 -> Kom Pan | DY27: ='Gen CP'!$L27 -> Kom Pan | EA27: ='Gen CP'!$L27 -> Kom Pan | EC27: 2:00-3:00 | EE27: ='Gen CP'!$M27 -> 0 | EG27: ='Gen CP'!$M27 -> 0 | EI27: ='Gen CP'!$M27 -> 0 | EK27: ='Gen CP'!$M27 -> 0 | EM27: ='Gen CP'!$M27 -> 0 | EO27: 2:00-3:00 | EP27: 60 | FA27: 2:00-3:00 | FB27: 60 | FM27: 2:00-3:00 | FN27: 60 | FY27: 2:00-3:00
C28: ='Gen CP'!$B28 -> Aguilar EM | E28: ='Gen CP'!$B28 -> Aguilar EM | G28: ='Gen CP'!$B28 -> Aguilar EM | I28: ='Gen CP'!$B28 -> Aguilar EM | K28: ='Gen CP'!$B28 -> Aguilar EM | O28: ='Gen CP'!$C28 -> Marcelo OJ | Q28: ='Gen CP'!$C28 -> Marcelo OJ | S28: ='Gen CP'!$C28 -> Marcelo OJ | U28: ='Gen CP'!$C28 -> Marcelo OJ | W28: ='Gen CP'!$C28 -> Marcelo OJ | AA28: ='Gen CP'!$D28 -> Coronel R | AC28: ='Gen CP'!$D28 -> Coronel R | AE28: ='Gen CP'!$D28 -> Coronel R | AG28: ='Gen CP'!$D28 -> Coronel R | AI28: ='Gen CP'!$D28 -> Coronel R | AM28: ='Gen CP'!$E28 -> Reyes D | AO28: ='Gen CP'!$E28 -> Reyes D | AQ28: ='Gen CP'!$E28 -> Reyes D | AS28: ='Gen CP'!$E28 -> Reyes D | AU28: ='Gen CP'!$E28 -> Reyes D | AY28: ='Gen CP'!$F28 -> Mercado R | BA28: ='Gen CP'!$F28 -> Mercado R | BC28: ='Gen CP'!$F28 -> Mercado R | BE28: ='Gen CP'!$F28 -> Mercado R | BG28: ='Gen CP'!$F28 -> Mercado R | BK28: ='Gen CP'!$G28 -> Domingo V | BM28: ='Gen CP'!$G28 -> Domingo V | BO28: ='Gen CP'!$G28 -> Domingo V | BQ28: ='Gen CP'!$G28 -> Domingo V | BS28: ='Gen CP'!$G28 -> Domingo V | BW28: ='Gen CP'!$H28 -> Sagnip M | BY28: ='Gen CP'!$H28 -> Sagnip M | CA28: ='Gen CP'!$H28 -> Sagnip M | CC28: ='Gen CP'!$H28 -> Sagnip M | CE28: ='Gen CP'!$H28 -> Sagnip M | CI28: ='Gen CP'!$I28 -> Guerrero LG | CK28: ='Gen CP'!$I28 -> Guerrero LG | CM28: ='Gen CP'!$I28 -> Guerrero LG | CO28: ='Gen CP'!$I28 -> Guerrero LG | CQ28: ='Gen CP'!$I28 -> Guerrero LG | CU28: ='Gen CP'!$J28 -> Almazan AD | CW28: ='Gen CP'!$J28 -> Almazan AD | CY28: ='Gen CP'!$J28 -> Almazan AD | DA28: ='Gen CP'!$J28 -> Almazan AD | DC28: ='Gen CP'!$J28 -> Almazan AD | DG28: ='Gen CP'!$K28 -> Almadin H | DI28: ='Gen CP'!$K28 -> Almadin H | DK28: ='Gen CP'!$K28 -> Almadin H | DM28: ='Gen CP'!$K28 -> Almadin H | DO28: ='Gen CP'!$K28 -> Almadin H | DS28: ='Gen CP'!$L28 -> Pascua I | DU28: ='Gen CP'!$L28 -> Pascua I | DW28: ='Gen CP'!$L28 -> Pascua I | DY28: ='Gen CP'!$L28 -> Pascua I | EA28: ='Gen CP'!$L28 -> Pascua I | EE28: ='Gen CP'!$M28 -> 0 | EG28: ='Gen CP'!$M28 -> 0 | EI28: ='Gen CP'!$M28 -> 0 | EK28: ='Gen CP'!$M28 -> 0 | EM28: ='Gen CP'!$M28 -> 0
A29: 1:50-2:40 | C29: ='Gen CP'!$B29 -> Emp Tech | E29: ='Gen CP'!$B29 -> Emp Tech | G29: ='Gen CP'!$B29 -> Emp Tech | I29: ='Gen CP'!$B29 -> Emp Tech | K29: ='Gen CP'!$B29 -> Emp Tech | M29: 1:50-2:40 | O29: ='Gen CP'!$C29 -> Emp Tech | Q29: ='Gen CP'!$C29 -> Emp Tech | S29: ='Gen CP'!$C29 -> Emp Tech | U29: ='Gen CP'!$C29 -> Emp Tech | W29: ='Gen CP'!$C29 -> Emp Tech | Y29: 1:50-2:40 | AA29: ='Gen CP'!$D29 -> Earth & Life | AC29: ='Gen CP'!$D29 -> Earth & Life | AE29: ='Gen CP'!$D29 -> Earth & Life | AG29: ='Gen CP'!$D29 -> Earth & Life | AI29: ='Gen CP'!$D29 -> Earth & Life | AK29: 1:50-2:40 | AM29: ='Gen CP'!$E29 -> Gen Math | AO29: ='Gen CP'!$E29 -> Gen Math | AQ29: ='Gen CP'!$E29 -> Gen Math | AS29: ='Gen CP'!$E29 -> Gen Math | AU29: ='Gen CP'!$E29 -> Gen Math | AW29: 1:50-2:40 | AY29: ='Gen CP'!$F29 -> MIL | BA29: ='Gen CP'!$F29 -> MIL | BC29: ='Gen CP'!$F29 -> MIL | BE29: ='Gen CP'!$F29 -> MIL | BG29: 21st Cen Lit | BI29: 1:50-2:40 | BK29: ='Gen CP'!$G29 -> Kom Pan | BM29: ='Gen CP'!$G29 -> Kom Pan | BO29: ='Gen CP'!$G29 -> Kom Pan | BQ29: ='Gen CP'!$G29 -> Kom Pan | BS29: ='Gen CP'!$G29 -> Kom Pan | BU29: 1:50-2:40 | BW29: ='Gen CP'!$H29 -> Kom Pan | BY29: ='Gen CP'!$H29 -> Kom Pan | CA29: ='Gen CP'!$H29 -> Kom Pan | CC29: ='Gen CP'!$H29 -> Kom Pan | CE29: Agri-Crops NC II | CG29: 1:50-2:40 1:50-2:50 | CI29: ='Gen CP'!$I29 -> UCSP | CK29: ='Gen CP'!$I29 -> UCSP | CM29: ='Gen CP'!$I29 -> UCSP | CO29: ='Gen CP'!$I29 -> UCSP | CQ29: ='Gen CP'!$I29 -> UCSP | CS29: 1:50-2:40 | CU29: ='Gen CP'!$J29 -> UCSP | CW29: ='Gen CP'!$J29 -> UCSP | CY29: ='Gen CP'!$J29 -> UCSP | DA29: ='Gen CP'!$J29 -> UCSP | DC29: ='Gen CP'!$J29 -> UCSP | DE29: 1:50-2:40 | DG29: ='Gen CP'!$K29 -> Oral Com | DI29: ='Gen CP'!$K29 -> Oral Com | DK29: ='Gen CP'!$K29 -> Oral Com | DM29: ='Gen CP'!$K29 -> Oral Com | DO29: ='Gen CP'!$K29 -> Oral Com | DQ29: 2:10-3:00 | DS29: ='Gen CP'!$L29 -> Emp Tech | DU29: ='Gen CP'!$L29 -> Emp Tech | DW29: ='Gen CP'!$L29 -> Emp Tech | DY29: ='Gen CP'!$L29 -> Emp Tech | EA29: ='Gen CP'!$L29 -> Emp Tech | EC29: 3:00-4:00 | EE29: ='Gen CP'!$M29 -> 0 | EG29: ='Gen CP'!$M29 -> 0 | EI29: ='Gen CP'!$M29 -> 0 | EK29: ='Gen CP'!$M29 -> 0 | EM29: ='Gen CP'!$M29 -> 0 | EO29: 3:00-4:00 | EY29: Flag Retreat | FA29: 3:00-4:00 | FK29: Flag Retreat | FM29: 3:00-4:00 | FW29: Flag Retreat | FY29: 3:00-4:00
